Workbook
Name Requerimientos_Instrumental: 'REQ. FUN. GEN'!$C$8

Sheet GENERAL
K5: RESUMEN REQUERIMIENTOS
F6: TOTAL | G6: CUMPLE | H6: NO CUMPLE
C7: * Requisitos de usuario | F7: ='REQ. USUARIO'!E19 -> 52 | G7: ='REQ. USUARIO'!C16 -> 38 | H7: ='REQ. USUARIO'!G16 -> 14
K8: TOTAL | O8: CUMPLIDOS | S8: NO CUMPLIDOS
C9: * Requisitos funcionales | F9: ='REQ. FUN. GEN'!N26 -> 356 | G9: ='REQ. FUN. GEN'!L23 -> 318 | H9: ='REQ. FUN. GEN'!P23 -> 38 | K9: =SUM(F7,F9,F11) -> 725 | O9: =SUM(G7,G9,G11) -> 647 | S9: =SUM(H7,H9,H11) -> 78
C11: * Requisitos no funcionales | F11: ='REQ. NO FUN. GEN'!N26 -> 317 | G11: ='REQ. NO FUN. GEN'!L23 -> 291 | H11: ='REQ. NO FUN. GEN'!P23 -> 26
C14: Porcentaje real | E14: =O9/K9 -> 0.89241379
C16: Inventario Transacciones

Sheet REQ. USUARIO
G3: Cumple | H3: No cumple
C4: * Requisitos funcionales | G4: =COUNTIF('REQ. FUN'!M:M, "x") -> 24 | H4: =COUNTIF('REQ. FUN'!N:N, "x") -> 7
L5: Volver
C6: * Requisitos no funcionales | G6: =COUNTIF('REQ. NO FUN'!M:M, "x") -> 14 | H6: =COUNTIF('REQ. NO FUN'!N:N, "x") -> 7
C11: REQUERIMIENTOS USUARIO
C15: Cumplidos | G15: No cumplidos
C16: =SUM(G4:G6) -> 38 | G16: =SUM(H4:H6) -> 14
E18: Implementados
E19: =SUM(C16,G16) -> 52

Sheet REQ. FUN. GEN
F2: Cumple | G2: No cumple
C3: * Requerimientos Inicio / Landing | F3: =COUNTIF('PAG. WEB - Landing FUN.'!M:M, "x") -> 21 | G3: =COUNTIF('PAG. WEB - Landing FUN.'!N:N, "x") -> 7
C4: * Requerimientos Inicio de sesión | F4: =COUNTIF('Inicio de sesión FUN.'!M:M, "x") -> 35 | G4: =COUNTIF('Inicio de sesión FUN.'!N:N, "x") -> 2
C5: * Requerimientos Registro | F5: =COUNTIF('Registro FUN.'!M:M, "x") -> 28 | G5: =COUNTIF('Registro FUN.'!N:N, "x") -> 2
C6: * Requerimientos Panel Administrador | F6: =COUNTIF('Panel Admin FUN.'!M:M, "x") -> 42 | G6: =COUNTIF('Panel Admin FUN.'!N:N, "x") -> 4
C7: * Requerimientos Información Personal | F7: =COUNTIF('Inf. Personal FUN.'!M:M, "x") -> 31 | G7: =COUNTIF('Inf. Personal FUN.'!N:N, "x") -> 1
C8: * Requerimientos Instrumental | F8: =COUNTIF('Instrumental FUN.'!M:M, "x") -> 53 | G8: =COUNTIF('Instrumental FUN.'!N:N, "x") -> 2
C9: * Requerimientos Materia Prima | F9: =COUNTIF('Materia prima FUN.'!M:M, "x") -> 41 | G9: =COUNTIF('Materia prima FUN.'!N:N, "x") -> 1
C10: * Requerimientos Productos | F10: =COUNTIF('Productos FUN'!M:M, "x") -> 13 | G10: =COUNTIF('Productos FUN'!N:N, "x") -> 0
C11: * Requerimientos Finanzas | F11: =COUNTIF('Finanzas FUN'!M:M, "x") -> 9 | G11: =COUNTIF('Productos FUN'!N:N, "x") -> 0
C12: * Requerimientos Historial | F12: =COUNTIF('Historial FUN'!M:M, "x") -> 21 | G12: =COUNTIF('Historial FUN'!N:N, "x") -> 3
C13: * Requerimientos Clientes | F13: =COUNTIF('Clientes FUN'!M:M, "x") -> 7 | G13: =COUNTIF('Clientes FUN'!N:N, "x") -> 3
C14: * Requerimientos Facturación | F14: =COUNTIF('Facturación FUN.'!M:M, "x") -> 9 | G14: =COUNTIF('Facturación FUN.'!N:N, "x") -> 1
C17: * Gestión de Usuarios y Autenticación | F17: =COUNTIF('Gestión Usuarios FUN.'!M:M, "x") -> 6 | G17: =COUNTIF('Gestión Usuarios FUN.'!N:N, "x") -> 4
C18: * Gestión de Permisos y Menús | F18: =COUNTIF('Permisos y Menús FUN.'!M:M, "x") -> 2 | G18: =COUNTIF('Permisos y Menús FUN.'!N:N, "x") -> 8 | L18: REQUERIMIENTOS FUNCIONALES
L22: Cumplidos | P22: No cumplidos
L23: =SUM(F3:F14,F17:F18,P3:P7) -> 318 | P23: =SUM(G3:G14,G17:G18,Q3:Q7) -> 38
C24: Volver
N25: Implementados
N26: =SUM(L23,P23) -> 356

Sheet REQ. NO FUN. GEN
F2: Cumple | G2: No cumple
C3: * Requerimientos Inicio / Landing | F3: =COUNTIF('PAG. WEB - Landing NO FUN.'!M:M, "x") -> 28 | G3: =COUNTIF('PAG. WEB - Landing NO FUN.'!N:N, "x") -> 3
C4: * Requerimientos Inicio de sesión | F4: =COUNTIF('Inicio de sesión NO FUN.'!M:M, "x") -> 16 | G4: =COUNTIF('Inicio de sesión NO FUN.'!N:N, "x") -> 4
C5: * Requerimientos Registro | F5: =COUNTIF('Registro NO FUN.'!M:M, "x") -> 21 | G5: =COUNTIF('Registro NO FUN.'!N:N, "x") -> 2
C6: * Requerimientos Panel Administrador | F6: =COUNTIF('Panel Admin NO FUN.'!M:M, "x") -> 33 | G6: =COUNTIF('Panel Admin NO FUN.'!N:N, "x") -> 2
C7: * Requerimientos Información Personal | F7: =COUNTIF('Inf. Personal NO FUN.'!M:M, "x") -> 0 | G7: =COUNTIF('Inf. Personal NO FUN.'!N:N, "x") -> 0
C8: * Requerimientos Instrumental | F8: =COUNTIF('Instrumental NO FUN.'!M:M, "x") -> 37 | G8: =COUNTIF('Instrumental NO FUN.'!N:N, "x") -> 1
C9: * Requerimientos Materia Prima | F9: =COUNTIF('Materia prima NO FUN.'!M:M, "x") -> 13 | G9: =COUNTIF('Materia prima NO FUN.'!N:N, "x") -> 1
C10: * Requerimientos Productos | F10: =COUNTIF('Productos NO FUN'!M:M, "x") -> 27 | G10: =COUNTIF('Productos NO FUN'!N:N, "x") -> 0
C11: * Requerimientos Finanzas | F11: =COUNTIF('Finanzas NO FUN'!M:M, "x") -> 27 | G11: =COUNTIF('Finanzas NO FUN'!N:N, "x") -> 0
C12: * Requerimientos Historial | F12: =COUNTIF('Historial NO FUN.'!M:M, "x") -> 82 | G12: =COUNTIF('Historial NO FUN.'!N:N, "x") -> 0
C13: * Requerimientos Clientes | F13: =COUNTIF('Clientes NO FUN.'!M:M, "x") -> 3 | G13: =COUNTIF('Clientes NO FUN.'!N:N, "x") -> 2
C14: * Requerimientos Facturación | F14: =COUNTIF('Facturación NO FUN.'!M:M, "x") -> 2 | G14: =COUNTIF('Facturación NO FUN.'!N:N, "x") -> 3
C17: * Gestión de Usuarios y Autenticación | F17: =COUNTIF('Gestión Usuarios NO FUN.'!M:M, "x") -> 2 | G17: =COUNTIF('Gestión Usuarios NO FUN.'!N:N, "x") -> 3
C18: * Gestión de Permisos y Menús | F18: =COUNTIF('Permisos y Menús NO FUN.'!M:M, "x") -> 0 | G18: =COUNTIF('Permisos y Menús NO FUN.'!N:N, "x") -> 5 | L18: REQUERIMIENTOS NO FUNCIONALES
L22: Cumplidos | P22: No cumplidos
L23: =SUM(F3:F14,F17:F18,) -> 291 | P23: =SUM(G3:G14,G17:G18,Q3:Q7) -> 26
N25: Implementados
N26: =SUM(L23,P23) -> 317
C29: Volver

Sheet REQ. FUN
B2: SI | C2: Marque con una equis (X) si el sistema no cumple con la función descrita | T2: Volver
B3: NO | C3: Marque con una equis (X) si el sistema cumple con la función descrita
B4: ADI | C4: Marque con una equis (X) si el sistema debe adicionar la función descrita
B5: Observaciones: | D5: Espacio para complementar respuestas
B7: P
M8: Nivel de cumplimiento | P8: OBSERVACIONES
E9: REQUERIMIENTOS FUNCIONALES SPECIALIZED | M9: SI | N9: NO | O9: ADI
C11: Gestión de productos
B12: 1 | C12: El sistema contará con un módulo de gestión de catálogo. | M12: x
B13: 2 | C13: El sistema debe permitir actualizar la informacion de los productos disponibles. | M13: x
B14: 3 | C14: El sistema debe permitir eliminar los productos que ya no se deseen mostrar en el catálogo. | M14: x
C16: Almacenamiento de instrumental disponible
B17: 5 | C17: El sistema debe mostrar en tiempo real el stock disponible de cada producto. | M17: x
B18: 6 | C18: El sistema debe tener alertas automáticas cuando el stock de un producto sea inferior al normal establecido. | M18: x
C20: Control de inventario
B21: 8 | C21: El sistema debe registrar salidas de productos del inventario con detalles como fecha, cantidad y motivo (por ejemplo, venta o pérdida). | M21: x
B22: 9 | C22: Generar reportes automáticos de inventario para análisis periódico (Como los productos que más se vendieron en un mes). | M22: x
B23: 10 | C23: Permitir registrar información sobre la materia prima utilizada en la fabricación de productos, como proveedores, cantidades disponibles, costos unitarios y fechas de adquisición. | M23: x
C25: Gestión de proveedores
B26: 11 | C26: Registrar información detallada de proveedores, como nombre, dirección, teléfono, correo electrónico, productos suministrados y condiciones de compra. | M26: x
B27: 12 | C27: Permitir eliminar proveedores a los cuales ya no se les pide materia prima, o dejaron de proveer esta misma. | M27: x
B28: 13 | C28: Permitir actualizar proveedores en caso que se tenga que actualizar algún dato de estos. | M28: x
B29: 14 | C29: Incluir funcionalidades para realizar búsquedas rápidas y filtrar por nombre o tipo de producto suministrado. | N29: x
C31: Gestión de clientes
B32: 15 | C32: Permitir almacenar información de clientes, incluyendo nombre, tipo de cliente (profesional, estudiante, etc.), dirección, teléfono y correo electrónico. | M32: x
B33: 17 | C33: Permitir segmentar clientes según su tipo (estudiante, profesional, etc.) para personalizar ofertas y analizar patrones de compra. | N33: x
C35: Facturación
B36: 18 | C36: Generar facturas automáticamente al confirmar una venta, incluyendo información del cliente, productos vendidos, cantidades, precios unitarios, impuestos y totales. | M36: x
B37: 19 | C37: El sistema debe generar automáticamente una factura en formato PDF al confirmar una venta, El PDF deberá estar disponible para visualización, descarga e impresión. | M37: x
C39: Reportes
B40: 20 | C40: Generar reportes sobre ventas, inventario, ingresos, clientes y proveedores. | N40: x
B41: 21 | C41: Permitir la personalización de reportes para incluir filtros por fecha, categorías de productos, etc. | M41: x
C43: Gestión de precios
B44: 22 | C44: Permitir actualizar precios de productos. | M44: x
B45: 23 | C45: Implementar promociones o descuentos temporales con fechas de inicio y fin. | N45: x
C48: Gestión de devoluciones
B49: 25 | C49: Registrar devoluciones de productos, especificando el motivo, la cantidad devuelta y las acciones tomadas (reemplazo, reembolso, reparación). | M49: x
C52: Gestión de usuarios
B53: 27 | C53: Permitir la creación de cuentas de usuario (administrador o cliente). | M53: x
B54: 28 | C54: Implementar autenticación segura mediante contraseñas encriptadas y opciones de recuperación. | M54: x
...

Sheet REQ. NO FUN
A1: y e
B2: SI | C2: Marque con una equis (X) si el sistema no cumple con la función descrita | U2: Volver
B3: NO | C3: Marque con una equis (X) si el sistema cumple con la función descrita
B4: ADI | C4: Marque con una equis (X) si el sistema debe adicionar la función descrita
B5: Observaciones: | D5: Espacio para complementar respuestas
B7: P
M8: Nivel de cumplimiento | P8: OBSERVACIONES
D9: REQUERIMIENTOS NO FUNCIONALES SPECIALIZED | M9: SI | N9: NO | O9: ADI
C11: Seguridad
B12: 1 | C12: Proteger los datos de clientes, empleados y proveedores mediante algoritmos de encriptación. | M12: x
B13: 2 | C13: Encriptación de la contraseña del usuario del sistema. | M13: x
B14: 3 | C14: Implementar medidas contra ataques como SQL Injection. | M14: x
B15: 5 | C15: Si un usuario falla 3 veces al ingresar su contraseña, su cuenta se bloquea temporalmente. | N15: x
B16: 6 | C16: Accesos restringidos: Solo los jefes o administradores pueden ver informes médicos de empleados. | N16: x
C18: Desempeño
B19: 7 | C19: El tiempo de respuesta del sistema debe ser inferior a 3 segundos en operaciones comunes como la realización de búsquedas. | M19: x
B20: 8 | C20: Reportes rápidos: Generar un reporte de ventas mensual no debe tardar más de 10 segundos. | M20: x
C22: Escalabilidad
B23: 9 | C23: El sistema debe ser capaz de manejar un aumento en el número de usuarios. | M23: x
B24: 10 | C24: El sistema debe ser capaz de manejar un aumento en el número de productos sin afectar el rendimiento. | N24: x
B25: 11 | C25: El sistema debe ser capaz de manejar un aumento en el número de transacciones sin afectar el rendimiento. | N25: x
C27: Usabilidad
B28: 12 | C28: La interfaz del sistema debe ser intuitiva. | M28: x
B29: 13 | C29: La interfaz del sistema debe ser fácil de usar. | M29: x
C31: Compatibilidad
B32: 15 | C32: El sistema debe ser compatible con los principales navegadores web (Chrome, Firefox, Edge, Safari). | M32: x
B33: 16 | C33: Debe ser accesible desde dispositivos móviles, tabletas y computadoras de escritorio. | M33: x
B34: 17 | C34: Realizar copias de seguridad automáticas diariamente y permitir restauración rápida en caso de fallas. | N34: x
B35: 18 | C35: El sistema cumple con normativas locales e internacionales, como las leyes de protección de datos personales. | M35: x
C37: Mantenimiento
B38: 19 | C38: Restaurar información: Si se pierden datos, poder recuperarlos desde la última copia de seguridad. | N38: x
B39: 20 | C39: El sistema debe mostrar mensajes claros cuando hay errores (ej: "No se pudo guardar. Revise su conexión a internet"). | M39: x
C41: Otros
B42: 22 | C42: Leyes de privacidad: Cumplir con normas de protección de datos (ej: no compartir información de clientes sin permiso). | M42: x
B43: 23 | C43: El sistema debe poder imprimir facturas o reportes sin configurar nada extra. | M43: x
B44: 24 | C44: Logo visible: Mostrar el logo de la empresa en todas las pantallas importantes (facturas, reportes). | N44: x

Sheet PAG. WEB - Landing FUN.
B2: SI | C2: Marque con una equis (X) si el sistema no cumple con la función descrita | T2: Volver
B3: NO | C3: Marque con una equis (X) si el sistema cumple con la función descrita
B4: ADI | C4: Marque con una equis (X) si el sistema debe adicionar la función descrita
B5: Observaciones: | D5: Espacio para complementar respuestas
B7: P
M8: Nivel de cumplimiento | P8: OBSERVACIONES
D9: REQUERIMIENTOS GENERALES FUNCIONALES DE LA PÁGINA WEB - LANDING | M9: SI | N9: NO | O9: ADI
B12: 1 | C12: Mostrar menú superior con opciones de navegación | M12: x
B13: 2 | C13: Mostrar botón "Ingresar" en esquina superior derecha | M13: x
B14: 3 | C14: Búsqueda Dinámica: Filtrado de productos en tiempo real al ingresar caracteres (ej: "li"). | M14: x
B15: 4 | C15: Auto-cierre de Secciones: Al limpiar la búsqueda, las secciones desplegadas deben cerrarse solas. | M15: x
B16: 5 | C16: Controlador de Limpieza: Botón dedicado para resetear el campo de búsqueda de forma instantánea. | M16: x
B17: 6 | C17: Navegación por Tabs: Selección de categorías mediante botones de menú superior. | M17: x
B18: 7 | C18: Despliegue de Información: Mostrar descripción y productos al hacer clic en una categoría. | M18: x
B19: 8 | C19: Gestión de Cookies: Desplegar modal informativo antes de permitir el acceso al Login. | M19: x
B20: 9 | C20: Lógica de Redirección: El sistema debe redirigir al login tras interactuar con el modal de cookies. | M20: x
B21: 10 | C21: Visualización de Kits: Listado de instrumentos agrupados por especialidad dental. | M21: x
B22: 11 | C22: Botón "Ingresar": Enlace funcional hacia el módulo de autenticación. | M22: x
B23: 12 | C23: Visualización de Imágenes de Kits: Mostrar fotografías reales de los productos en el hover. | M23: x
... B27: 16 | C27: Mostrar mensaje de bienvenida al usuario. | M27: x
B28: 17 | C28: Carrusel de productos destacados. | N28: x
B29: 18 | C29: Barra de búsqueda en header. | M29: x
B30: 20 | C30: Enlace directo a WhatsApp de ventas. | M30: x
B31: 21 | C31: Etiqueta "Nuevo" en productos recientes. | N31: x
B32: 22 | C32: Botón "Volver arriba" en scroll. | N32: x | R32: Por el momento la página no tiene movimientos scroll
B33: 23 | C33: Vista rápida de productos. | M33: x
B34: 24 | C34: Sección de noticias o blog. | N34: x
B35: 26 | C35: Filtro por tipo de material (acero/liviano). | N35: x
B36: 27 | C36: Filtro por especialización dental. | M36: x
B37: 28 | C37: Descarga de catálogo en PDF. | N37: x
B38: 29 | C38: Vista de productos agotados. | N38: x
B39: 30 | C39: Estado de Carga: Mostrar nombres de productos y descripciones base incluso si la imagen falla. | M39: x

Sheet PAG. WEB - Landing NO FUN.
B2: SI | C2: Marque con una equis (X) si el sistema no cumple con la función descrita | V2: Volver
B3: NO | C3: Marque con una equis (X) si el sistema cumple con la función descrita
B4: ADI | C4: Marque con una equis (X) si el sistema debe adicionar la función descrita
B5: Observaciones: | D5: Espacio para complementar respuestas
B7: P
M8: Nivel de cumplimiento | P8: OBSERVACIONES
D9: REQUERIMIENTOS GENERALES NO FUNCIONALES DE LA PÁGINA WEB - LANDING | M9: SI | N9: NO | O9: ADI
B12: 1 | C12: Página carga en menos de 5 segundos. | M12: x | R12: Navegación con teclado posible
B13: 2 | C13: Colores verde, blanco y azul corporativos. | M13: x | R13: Seguridad básica contra hackers
B14: 3 | C14: Textos legibles y tamaño adecuado. | M14: x | R14: Contraseñas encriptadas en base de datos
B15: 4 | C15: Mostrar header con logo de la empresa. | M15: x
B16: 5 | C16: Identidad Corporativa: Header con degradado lineal (linear-gradient) verde y azul. | M16: x
B17: 6 | C17: Cambio de color de fondo y texto al pasar el mouse por los menús. | M17: x
B18: 7 | C18: Efecto de Elevación: Las cartas de producto deben subir (translateY) al pasar el mouse. | M18: x
B19: 8 | C19: Sombreado Dinámico: Aparición de sombras (box-shadow) profundas en elementos activos. | M19: x
B20: 9 | C20: Transiciones Suaves: Los efectos visuales deben durar 0.3s para mejorar la fluidez (UX). | M20: x
B21: 10 | C21: Cambio de brillo/oscuridad en el botón "Ingresar" al interactuar. | M21: x
B22: 11 | C22: Adaptabilidad (Responsive): Uso de Media Queries para que la web funcione en móviles. | M22: x
B23: 12 | C23: Arquitectura Limpia: Separación total de estilos (CSS) y estructura (HTML). Archivos independientes. | M23: x
B24: 13 | C24: Iconografía Estándar: Integración con FontAwesome para íconos del sistema. | M24: x | R24: iconos extraidos de otra web
B25: 14 | C25: Interfaz Intuitiva: Barra de búsqueda centrada y de fácil acceso visual. | M25: x
B26: 15 | C26: Iconografía Específica: Ícono de "escoba" para la limpieza de búsqueda. | N26: x
B27: 16 | C27: Imágenes no pixeladas. | M27: x
B28: 17 | C28: Formularios con validación básica. | M28: x
B29: 18 | C29: Links funcionan correctamente. | M29: x
B30: 19 | C30: Página no se cae con muchos usuarios. | M30: x | R30: Datos de clientes protegidos
B31: 20 | C31: Funciona en Edge y Safari también. | M31: x
B32: 21 | C32: Cambio de cursor a 'pointer' en botones y cartas. | M32: x
B33: 22 | C33: Suavizado de bordes: Interfaz con esquinas redondeadas para estética moderna. | M33: x
B34: 23 | C34: Optimización de carga: Scripts ubicados al final del body para mayor velocidad. | M34: x
B35: 24 | C35: Jerarquía visual: Títulos destacados con colores institucionales. | M35: x
B36: 25 | C36: Imágenes optimizadas para web. | N36: x
B37: 26 | C37: Formularios con mensajes de error claros. | M37: x
B38: 28 | C38: Compatible con lectores de pantalla. | N38: x
B39: 29 | C39: Cumplimiento ley de protección de datos. | M39: x
B40: 31 | C40: Escalable para más productos. | M40: x
B41: 32 | C41: Fácil de actualizar contenido. | M41: x
B42: 33 | C42: No requiere software especial. | M42: x

Sheet Inicio de sesión FUN.
B2: SI | C2: Marque con una equis (X) si el sistema no cumple con la función descrita | V2: Volver
B3: NO | C3: Marque con una equis (X) si el sistema cumple con la función descrita
B4: ADI | C4: Marque con una equis (X) si el sistema debe adicionar la función descrita
B5: Observaciones: | D5: Espacio para complementar respuestas
B7: P
M8: Nivel de cumplimiento | P8: OBSERVACIONES
D9: REQUERIMIENTOS FUNCIONALES DEL INICIO DE SESIÓN | M9: SI | N9: NO | O9: ADI
B12: 1 | C12: Mostrar formulario con campos "Usuario" y "Contraseña". | M12: x | R12: olvidar contraseña + olvidé usuario
B13: 2 | C13: Logo corporativo visible en pantalla de login. | N13: x
B14: 3 | C14: Campo contraseña con ocultación de caracteres. | M14: x
B15: 5 | C15: El sistema debe mostrar el panel de inicio de sesión. | M15: x
B16: 6 | C16: Botón "INICIAR SESIÓN" que envía datos al servidor. | M16: x
B17: 8 | C17: Enlace "¿Olvidaste tu contraseña?" funcional. | M17: x
B18: 9 | C18: Al dar click en "¿Olvidaste tu contraseña?" el sistema debe abrir un modal con el título "Recuperar Contraseña" y el mensaje "Ingresa tu nombre de usuario para buscar tu cuenta.". | M18: x
B19: 10 | C19: El modal debe mostrar un campo para ingresar el "Nombre de usuario" y si se ingresa un dato debe proceder a buscar el registro en el sistema, junto con el botón "Buscar" funcional. | M19: x
B20: 11 | C20: Si al dar click en el botón "Buscar" el campo está vacío el sistema debe mostrar un modal con el mensaje "Ingresa tu usuario" y un botón aceptar. | M20: x
B21: 12 | C21: Si al dar click en el botón "Buscar" y el campo contiene un user incorrecto, el sistema debe mostrar un modal con el mensaje "Usuario no encontrado" y un botón aceptar. | M21: x
B22: 13 | C22: El sistema debe verificar si el user ingresado corresponde a un usuario ya registrado, si el user no corresponde a un usuario el sistema debe mostrar un cuadro de modal que indique que el usuario no se encuentra. | M22: x
B23: 14 | C23: Si el user sí está registrado, el sistema debe abrir un nuevo modal con el título "Elige un método" y el mensaje "¿Cómo quieres recibir tu código de recuperación?". | M23: x
B24: 15 | C24: El modal debe mostrar dos opciones, la opción "Enviar a Email (correo_registrado@dominio.com)" y la opción "Enviar SMS (Télefono_registrado)". | M24: x
B25: 16 | C25: El modal debe mostrar el botón "Atrás" que regresa al modal de buscar usuario. | M25: x
... B43: 34 | C43: Mostrar/ocultar contraseña con ícono de ojo. | M43: x
B44: 35 | C44: Idioma seleccionable (ES/EN) en esquina superior. | N44: x
B45: 36 | C45: Validación de tiempo de sesión máxima configurable. | M45: x
B46: 37 | C46: Pantalla de términos y condiciones obligatoria en primer login. | M46: x
B47: 38 | C47: Pantalla de bienvenida personalizada tras login (con nombre). | M47: x
B48: 39 | C48: El sistema debe limpiar el historial de navegación para evitar que se pueda volver atrás tras cerrar sesión. | M48: x

Sheet Inicio de sesión NO FUN.
B2: SI | C2: Marque con una equis (X) si el sistema no cumple con la función descrita | V2: Volver
B3: NO | C3: Marque con una equis (X) si el sistema cumple con la función descrita
B4: ADI | C4: Marque con una equis (X) si el sistema debe adicionar la función descrita
B5: Observaciones: | D5: Espacio para complementar respuestas
B7: P
M8: Nivel de cumplimiento | P8: OBSERVACIONES
D9: REQUERIMIENTOS NO FUNCIONALES DEL INICIO DE SESIÓN | M9: SI | N9: NO | O9: ADI
B12: 1 | C12: Tiempo de respuesta < 2 segundos para validación de credenciales. | M12: x
B13: 2 | C13: Protección contra fuerza bruta con límite de intentos. | N13: x
B14: 3 | C14: Consistencia visual con paleta corporativa (verde, azul, blanco). | M14: x
B15: 4 | C15: Logs de auditoría de intentos de login (éxito/fracaso). | N15: x
B16: 5 | C16: Validación de entrada contra SQL Injection. | M16: x
B17: 6 | C17: Manejo de errores sin mostrar detalles técnicos al usuario. | M17: x
B18: 7 | C18: Carga inicial < 3 segundos en conexión de 10 Mbps. | M18: x
B19: 8 | C19: Compatibilidad con lectores de pantalla básica. | N19: x
B20: 9 | C20: Soporte para teclado (navegación completa sin mouse). | M20: x
B21: 10 | C21: Backend en PHP 7.4+ con buenas prácticas de codificación. | M21: x
B22: 11 | C22: Base de datos normalizada con índices para búsquedas de usuarios. | M22: x
B23: 12 | C23: Mensajes de error en español claro y amigable. | M23: x
B24: 13 | C24: No almacena contraseñas en texto plano ni logs. | M24: x
B25: 14 | C25: Doble validación del token de sesión (server-side + client-side). | N25: x
B26: 15 | C26: Los títulos y mensajes motivacionales deben cambiar de color suavemente al pasar el mouse. | M26: x
B27: 16 | C27: Uso de fuentes diferenciadas (Montserrat para títulos, Arial para cuerpo) para mejorar la lectura. | M27: x
B28: 17 | C28: Los bordes de los campos deben resaltar en azul y expandirse al ser seleccionados por el usuario. | M28: x
B29: 18 | C29: Los títulos (h1) deben cambiar de color suavemente al pasar el puntero sobre ellos. | M29: x
B30: 19 | C30: Separación total de la lógica de autenticación (JS) y los estilos visuales (CSS) en archivos externos. | M30: x
B31: 20 | C31: Los scripts de lógica deben cargarse al final del body para no retrasar la visualización del formulario. | M31: x

Sheet Registro FUN.
B2: SI | C2: Marque con una equis (X) si el sistema no cumple con la función descrita | V2: Volver
B3: NO | C3: Marque con una equis (X) si el sistema cumple con la función descrita
B4: ADI | C4: Marque con una equis (X) si el sistema debe adicionar la función descrita
B5: Observaciones: | D5: Espacio para complementar respuestas
B7: P
M8: Nivel de cumplimiento | P8: OBSERVACIONES
D9: REQUERIMIENTOS FUNCIONALES DE LA PÁGINA WEB | M9: SI | N9: NO | O9: ADI
B12: 1 | C12: Mostrar formulario de registro con campos: "Usuario", "Correo electrónico", "Contraseña", "Teléfono". | M12: x
B13: 2 | C13: Botón "REGISTRARSE" que envía datos al servidor. | M13: x
B14: 3 | C14: Mensaje de éxito "Registro completado" tras envío exitoso. | M14: x
B15: 4 | C15: Validación en tiempo real de campos obligatorios. | M15: x
B16: 5 | C16: Redirección automática a login tras registro exitoso. | M16: x
B17: 6 | C17: Sección "¡Hola, Amigo!" con mensaje motivacional junto enlace "INICIAR SESIÓN" visible y funcional. | M17: x
B18: 7 | C18: Validación de formato de correo electrónico (con @ y dominio). | M18: x
B19: 8 | C19: Verificación de que correo no esté ya registrado. | M19: x
B20: 9 | C20: Mínimo 8 caracteres para contraseña. | M20: x
B21: 10 | C21: Mensaje de error específico por campo (ej: "Correo ya registrado"). | M21: x
B22: 11 | C22: Campos marcados con asterisco (*) para indicar obligatoriedad. | M22: x
B23: 12 | C23: Logo corporativo visible en pantalla de registro. | N23: x
B24: 14 | C24: Campos con etiquetas claras en español. | M24: x
B25: 15 | C25: Validación contra inyección SQL en todos los campos. | M25: x
B26: 16 | C26: Bloqueo de envíos múltiples (prevenir doble clic en botón). | N26: x
B27: 17 | C27: Compatibilidad con navegación por teclado (Tab). | M27: x
B28: 18 | C28: Campo de contraseña con máscara de caracteres por defecto. | M28: x
B29: 19 | C29: Mostrar/ocultar contraseña con ícono de ojo en ambos campos. | M29: x
B30: 20 | C30: Indicador visual de fortaleza de contraseña (Falta una mayúscula, Falta un número, etc). | M30: x
B31: 21 | C31: Validación de fortaleza de contraseña (mínimo 1 mayúscula, 1 número). | M31: x
B32: 22 | C32: Checkbox "Acepto términos y condiciones" obligatorio. | M32: x
B33: 23 | C33: Enlace a términos y condiciones en nueva ventana. | M33: x
B34: 25 | C34: El campo de contraseña debe restringir el ingreso a menos de 8 caracteres. | M34: x
B35: 26 | C35: Al finalizar el registro el sistema debe mostrar un cuadro de texto que indique que el registro fue completado con éxito. | M35: x
B36: 27 | C36: El sistema debe eliminar espacios en blanco accidentales en usuario y correo antes de procesarlos (Trim). | M36: x
B37: 28 | C37: El sistema debe filtrar y eliminar cualquier carácter no numérico del campo teléfono. | M37: x
B38: 29 | C38: El sistema debe asegurar que si falla la asignación de permisos, el usuario no se cree (Rollback si algo sale mal). | M38: x
... B41: 32 | C41: Restringir el registro si el nombre de usuario tiene menos de 3 caracteres. | M41: x

Sheet Registro NO FUN.
B2: SI | C2: Marque con una equis (X) si el sistema no cumple con la función descrita | V2: Volver
B3: NO | C3: Marque con una equis (X) si el sistema cumple con la función descrita
B4: ADI | C4: Marque con una equis (X) si el sistema debe adicionar la función descrita
B5: Observaciones: | D5: Espacio para complementar respuestas
B7: P
M8: Nivel de cumplimiento | P8: OBSERVACIONES | S8: Diseño responsivo para móviles (probado en 320px+)
D9: REQUERIMIENTOS NO FUNCIONALES DE LA PÁGINA WEB | M9: SI | N9: NO | O9: ADI
B12: 1 | C12: Tiempo de respuesta < 3 segundos para procesar registro. | M12: x
B13: 2 | C13: Almacenamiento seguro de contraseñas con hash. | M13: x
B14: 3 | C14: Validación server-side además de client-side. | M14: x | R14: PHP valida longitud, formato de email y duplicados.
B15: 4 | C15: Contraste de colores adecuado para lectura. | M15: x
B16: 5 | C16: Mensajes de error en español claro y amigable. | M16: x
B17: 6 | C17: Logs de nuevos registros con fecha y hora. | M17: x
B18: 7 | C18: Protección contra spam con límite de registros por IP. | N18: x
B19: 8 | C19: Base de datos PostgreSQL con índices para búsqueda rápida | M19: x
B20: 9 | C20: Validación de entradas contra XSS y SQL injection. | M20: x | R20: Las sentencias preparadas del PHP lo cubren.
B21: 10 | C21: Cookies seguras para sesión post-registro. | M21: x
B22: 11 | C22: Backend PHP 7.4+ con prácticas básicas de seguridad. | M22: x | R22: Pruebas manuales realizadas en formulario de registro
B23: 13 | C23: Manejo de excepciones básico (no muestra errores técnicos). | M23: x
B24: 14 | C24: Consistencia visual con resto del sistema. | M24: x
B25: 15 | C25: Espaciado adecuado entre elementos del formulario. | M25: x
B26: 19 | C26: Sistema de alertas por registro sospechoso (muchos intentos). | N26: x
B27: 20 | C27: Soporte para nombres largos (hasta 50 caracteres sin truncar). | M27: x
B28: 21 | C28: Los títulos y mensajes motivacionales deben cambiar de color suavemente al pasar el mouse. | M28: x
B29: 22 | C29: Uso de fuentes diferenciadas (Montserrat para títulos, Arial para cuerpo) para mejorar la lectura. | M29: x
B30: 23 | C30: Bloquear la carga de la página de registro en marcos o iframes externos. | M30: x | R30: X-Frame-Options: DENY
B31: 24 | C31: No enviar información del sitio de origen al navegar a enlaces externos. | M31: x
B32: 25 | C32: Impedir que los datos sensibles del formulario se almacenen en el caché del navegador. | M32: x | R32: Cache-Control: no-store
B33: 26 | C33: El backend debe exigir tipos de datos exactos para minimizar errores de lógica. | M33: x
B34: 27 | C34: La lógica de acceso a la base de datos debe residir en un archivo independiente y protegido. | M34: x

Sheet Inf. Personal FUN.
B2: SI | C2: Marque con una equis (X) si el sistema no cumple con la función descrita | V2: Volver
B3: NO | C3: Marque con una equis (X) si el sistema cumple con la función descrita
B4: ADI | C4: Marque con una equis (X) si el sistema debe adicionar la función descrita
B5: Observaciones: | D5: Espacio para complementar respuestas
M8: Nivel de cumplimiento | P8: OBSERVACIONES
D9: REQUERIMIENTOS FUNCIONALES DE CLIENTE DE LA PÁGINA WEB | M9: SI | N9: NO | O9: ADI
B12: 1 | C12: Al iniciar como cliente, el sistema debe mostrar un header con: Logo Specialized, Nombre Specialized, Barra de búsqueda, Botón de carrito, Icono de usuario junto a su nombre, botón de salir. | M12: x
B13: 2 | C13: Tanto el logo como el nombre "Specialized" al momento de dar click deben redirigir al inicio del scroll de la página de cliente. | M13: x
B14: 3 | C14: La barra de búsqueda debe ser dinámica e ir mostrando resultados según lo que se escriba, si se borra el buscado, el sistema debe volver a mostrar todos los productos. | M14: x
B15: 4 | C15: EL botón de carrito debe desplegar un menú derecho (sidebar). | M15: x
B16: 5 | C16: El carrito, si no hay productos añadidos debe mostrar un botón "Ver Productos" que al dar click cierra el menú de carrito y vuelve a la vista principal de productos. | M16: x
B17: 6 | C17: Al añadir productos al carrito, el icono de este en la parte superior derecha debe mostrar un circulo rojo con el numero exacto que se añada al carrito. | M17: x
B18: 7 | C18: Al tener productos añadidos, en el menú (sidebar) de carrito, deben aparecer los productos con su nombre, precio, una opción para añadir o reducir cantidades y un botón con ícono de basura para eliminar el ítem. | M18: x
B19: 8 | C19: Si se reduce más de 1 cantidad, el producto desaparece del carrito. | M19: x
B20: 9 | C20: En la parte inferior del sidebar de carrito, el sistema debe calcular el total de productos añadidos al carrito. | M20: x
B21: 10 | C21: Al hacer click en el botón "Proceder al Pago ->" el sistema debe mostrar un modal con el mensaje "Funcionalidad de pago próximamente". | M21: x
B22: 11 | C22: Al dar click en el ícono de usuario, junto al nombre, el sistema debe desplegar un modal con el nombre "Modificar Perfil", con los campos: (Nombre de Usuario, Email, Télefono). | M22: x
B23: 12 | C23: El modal debe contener los datos del usuario actual en los campos correspondientes. | M23: x
... B34: 23 | C34: El botón "Aceptar" debe redirigir a la landing, el botón "Cancelar" debe mantener la sesión y cerrar el modal. | M34: x
B35: 24 | C35: Antes de la sección de productos debe haber un título y una descripción del sistema "SDI (Special Dental Instruments)". | N35: x | R35: el sistema es de admin
B36: 25 | C36: La sección de productos debe tener las siguientes etiquetas de filtro: "Todos, Estética, Esterilización, Endodoncia, Periodoncia, Kits". | M36: x
B37: 26 | C37: Los filtros deben ser funcionales, al dar click a algún filtro debe traer los productos de la categoría seleccionada. | M37: x
B38: 27 | C38: Los productos deben estar contenidos en tarjetas, con una etiqueta distintiva de su categoría, su imagen, su nombre, su descripción y su precio. | M38: x
B39: 28 | C39: Cada tarjeta debe tener un botón "+" que al dar click debe añadir el producto al carrito. | M39: x
B40: 29 | C40: La página debe tener un scroll funcional. | M40: x
B41: 30 | C41: Al expirar el tiempo del token, el sistema debe mostrar un modal con el título "Sesión Caducada", con el mensaje "Tu sesión se ha cerrado automáticamente por seguridad debido a inactividad o expiración del token." | M41: x
B42: 31 | C42: El modal de "sesión caducada" debe contener un botón "Aceptar y Salir" que al dar click en este, debe cerrar la sesión automáticamente y redirigir a la landing. | M42: x
B43: 32 | C43: El sistema no debe mostrar este icono si el usuario no ha iniciado sesión. | M43: x

Sheet Inf. Personal NO FUN.
B2: SI | C2: Marque con una equis (X) si el sistema no cumple con la función descrita | V2: Volver
B3: NO | C3: Marque con una equis (X) si el sistema cumple con la función descrita
B4: ADI | C4: Marque con una equis (X) si el sistema debe adicionar la función descrita
B5: Observaciones: | D5: Espacio para complementar respuestas
B7: P
M8: Nivel de cumplimiento | P8: OBSERVACIONES
D9: REQUERIMIENTOS FUNCIONALES DE LA PÁGINA WEB | M9: SI | N9: NO | O9: ADI
B12: 1
B13: 2
B14: 3
B15: 4
B16: 5
B17: 6
B18: 7
B19: 8
B20: 9

Sheet Panel Admin FUN.
B2: SI | C2: Marque con una equis (X) si el sistema no cumple con la función descrita | V2: Volver
B3: NO | C3: Marque con una equis (X) si el sistema cumple con la función descrita
B4: ADI | C4: Marque con una equis (X) si el sistema debe adicionar la función descrita
B5: Observaciones: | D5: Espacio para complementar respuestas
B7: P
M8: Nivel de cumplimiento | P8: OBSERVACIONES
C9: REQUERIMIENTOS FUNCIONALES DEL PANEL ADMINISTRADOR DE LA PÁGINA WEB | M9: SI | N9: NO | O9: ADI
B12: 1 | C12: Al entrar se carga un dashboard centralizado con métricas clave de la plataforma. | M12: x
B13: 2 | C13: Saludo dinámico y personalizado con el nombre del usuario en sesión. | M13: x
B14: 3 | C14: Tarjetas de métrica (Total Usuarios, Nuevos este mes, Empleados, Clientes, Proveedores, Productos en inventario, mayor venta, Menor producto en stock) conectadas a la base de datos. | M14: x
B15: 4 | C15: Interacción Dinámica de Métricas: Al accionar (click) cualquier tarjeta de estadísticas, el sistema debe inicializar y desplegar un modal de gestión contextualizado al módulo de la métrica seleccionada (Excepto en las tarjetas "Mayor venta" y "Menor producto en stock". | M15: x
B16: 5 | C16: La tarjeta "Productos en inventario" al hacer click sobre ella, el sistema debe redirigir al menú "Productos" para realizar la gestión correspondiente. | M16: x
B17: 6 | C17: Renderizado de Grillas de Datos: El cuerpo del modal debe visualizar una lista detallada con los campos técnicos correspondientes (ID, Nombre, Contacto, Estado, etc.) consultados en tiempo real desde la DB. | M17: x
B18: 7 | C18: Estandarización de Modales de Inserción: Al presionar "Nuevo" en cualquier modal de gestión, el sistema debe desplegar un formulario dinámico con los campos obligatorios correspondientes al módulo. | M18: x
B19: 8 | C19: El sistema debe restringir automáticamente la visibilidad del botón "Nuevo" en el modal de la tarjeta "Nuevos este mes", permitiendo únicamente funciones de consulta y desplegar una lista con los usuarios registrados en el mes actual con los campos (ID, Usuario, Email, Teléfono, Fecha Registro, Acciones). | M19: x
B20: 9 | C20: Gestión de Cierre y Navegación: El modal debe contar con un botón "Cerrar" en la parte inferior y una "X" en la esquina superior derecha que finalice la instancia del objeto modal y retorne el foco a la vista general del Panel de Administración. | M20: x
B21: 10 | C21: Validación Universal de Entradas: Todos los campos de entrada de datos en los modales deben contar con validaciones de tipo de dato, longitud mínima/máxima y obligatoriedad antes de ser enviados. | M21: x
B22: 11 | C22: Manejo de Errores desde la Base de Datos: El sistema debe capturar las excepciones lanzadas por PostgreSQL (ej. Violación de unicidad) y mostrar un mensaje claro al administrador sin interrumpir el flujo. | M22: x
B23: 12 | C23: Lógica de Borrado Lógico (Soft Delete): La eliminación de cualquier registro desde el panel administrativo debe realizarse mediante la actualización del campo ind_vivo a FALSE, manteniendo la integridad referencial. | M23: x
... B26: 15 | C26: Confirmación de Acciones Críticas: Antes de ejecutar un borrado o una actualización masiva, el sistema debe solicitar una confirmación visual al usuario para prevenir errores accidentales. | M26: x
B27: 16 | C27: Integración de Búsqueda en Listados: Todo modal que visualice una lista (Usuarios, Clientes, etc.) debe integrar un campo de filtrado por nombre o ID para localización rápida de registros. | N27: x
B28: 17 | C28: Reporte de Nuevos Registros: Filtrar y mostrar automáticamente los usuarios registrados cuya fecha de inserción corresponda al mes calendario actual. | M28: x
B29: 18 | C29: Gestión Centralizada de Empleados: Visualizar y gestionar datos técnicos del personal (Cargos, ID de documento, Estado contractual) mediante el modal de Empleados. | M29: x
B30: 19 | C30: Consolidado de Gestión de Clientes: Desplegar el listado de clientes profesionales y estudiantes con su respectiva información de contacto y ubicación. | M30: x
B31: 20 | C31: Visibilidad de Inventario General: La tarjeta de Gestión "Productos en inventario" debe consolidar la sumatoria de todos los instrumentos y kits que tengan el estado ind_vivo = TRUE. | M31: x
B32: 21 | C32: En el campo "Acciones" de las tarjetas deben haber dos botones funcionales para "Editar" y "Eliminar". | M32: x
B33: 22 | C33: Visualización de "Total Ventas" con montos acumulados de la DB en la esquina inferior derecha. | M33: x
B34: 23 | C34: Reporte rápido de "Ventas Diarias" en la sección de analítica en la esquina inferior derecha. | M34: x
B35: 24 | C35: El sistema debe mostrar un menú lateral izquierdo funcional con los accesos directos a "Instrumental", "Materia Prima", "Productos", "Finanzas","Historial". | M35: x
B36: 25 | C36: Botón "Instrumental" redirecciona a la gestión de productos y kits. | M36: x
B37: 26 | C37: Botón "Materia Prima" redirecciona a la gestión de la materia prima. | M37: x
B38: 27 | C38: Botón "Productos" redirecciona a la gestión de los productos comerciales. | M38: x
B39: 28 | C39: Botón "Finanzas" redirecciona a la gestión de las finanzas de la empresa. | M39: x
B40: 29 | C40: Botón "Historial" redirecciona a la gestión de historiales de la empresa. | M40: x
B41: 30 | C41: El sistema debe mostrar un menú lateral derecho (panel de configuración) que contenga de forma visible las opciones: "Modificar Perfil", "Cambiar Contraseña", "Configuración", "Exportar Datos", "Ayuda y Soporte" y "Cerrar Sesión". | M41: x | R41: agregar otras opciones detalladamente
B42: 31 | C42: Al accionar la opción "Modificar Perfil" desde el menú, el sistema debe desplegar un modal con los campos (Nombre de usuario, Email, Teléfono, Rol), permitiendo al administrador editar su información, guardar cambios con mensaje de éxito o cancelar la operación retornando al dashboard. | M42: x
B43: 32 | C43: Al accionar la opción "Cambiar Contraseña" desde el menú, el sistema debe desplegar un modal con los campos (Contraseña Actual, Nueva, Confirmación), validando la coincidencia de datos y confirmando el cambio exitoso mediante un mensaje emergente. | M43: x
B44: 33 | C44: Opción "Notificaciones", abre un modal que muestra de manera rápida si hay o no productos / materias primas que se encuentran en bajo stock. | M44: x
B45: 34 | C45: Opción "Configuración" accesible desde el panel. | M45: x
B46: 35 | C46: Opción "Ayuda y Soporte" abre un modal con los datós básicos de contacto de los desarrolladores del sistema. | M46: x
...

Sheet Panel Admin NO FUN.
B2: SI | C2: Marque con una equis (X) si el sistema no cumple con la función descrita | V2: Volver
B3: NO | C3: Marque con una equis (X) si el sistema cumple con la función descrita
B4: ADI | C4: Marque con una equis (X) si el sistema debe adicionar la función descrita
B5: Observaciones: | D5: Espacio para complementar respuestas
B7: P
M8: Nivel de cumplimiento | P8: OBSERVACIONES
D9: REQUERIMIENTOS NO FUNCIONALES DEL PANEL ADMINISTRADOR | M9: SI | N9: NO | O9: ADI
B12: 1 | C12: El Dashboard debe reordenar las tarjetas en botones simples en la parte inferior al ser visto desde tablets. | M12: x
B13: 2 | C13: Efecto de elevación (floating effect) en tarjetas de métricas. | M13: x
B14: 3 | C14: Sombreado dinámico (box-shadow) al interactuar con elementos. | M14: x
B15: 4 | C15: Cambio de color suave en botones y opciones al pasar el mouse. | M15: x
B16: 5 | C16: Consistencia visual con paleta corporativa (Verde #087d4e / Azul #36498f). | M16: x
B17: 6 | C17: Transiciones fluidas de 0.3s en todos los efectos de hover. | M17: x
B18: 7 | C18: Diseño responsivo basado en Grid que se adapta a tablets. | M18: x
B19: 8 | C19: Sanitización de salida mediante htmlspecialchars() para prevenir XSS. | N19: x
B20: 9 | C20: Arquitectura modular con separación de Header, Sidebar y Footer. | M20: x
B21: 10 | C21: Cursor tipo 'pointer' habilitado en todas las tarjetas clicables. | M21: x
B22: 11 | C22: Iconografía estandarizada de FontAwesome para cada función. | M22: x
B23: 12 | C23: Tipografía profesional 'Montserrat' para títulos y 'Arial' para datos. | M23: x
B24: 13 | C24: Tiempo de carga inicial del dashboard inferior a 2 segundos. | M24: x
B25: 14 | C25: Contraste de color alto entre cifras numéricas y fondo de tarjetas. | M25: x
B26: 15 | C26: Código backend con tipado estricto (strict_types=1). | M26: x
B27: 16 | C27: Estilos CSS organizados en archivos externos independientes. | M27: x
B28: 17 | C28: Protección contra ataques de Clickjacking en el panel. | N28: x
B29: 18 | C29: Navegación intuitiva que no requiere curva de aprendizaje. | M29: x
B30: 19 | C30: Mensajes de error amigables sin exponer variables de sistema. | M30: x
B31: 20 | C31: Uso de variables CSS para consistencia de colores globales. | M31: x
B32: 21 | C32: Optimización de scripts JS al final del documento. | M32: x
B33: 22 | C33: Diseño de botones con bordes redondeados (15px) para estética moderna. | M33: x
B34: 23 | C34: Visualización limpia de tablas de datos sin saturación visual. | M34: x
B35: 24 | C35: El sistema debe resaltar el borde de las opciones del menú izquierdo en color blanco al detectar el evento hover. | M35: x
B36: 25 | C36: Las opciones del menú izquierdo deben incrementar su tamaño relativo respecto a los elementos adyacentes al pasar el mouse. | M36: x
B37: 26 | C37: El comportamiento de resaltado y escalado debe ser consistente tanto en el menú lateral izquierdo como en el derecho. | M37: x
B38: 27 | C38: La opción de menú seleccionada debe mantener un distintivo visual permanente mientras el administrador esté en ese módulo. | M38: x
B39: 28 | C39: El agrandamiento de los botones no debe desplazar o desordenar los elementos de contenido central del Dashboard. | M39: x
B40: 30 | C40: Todos los modales deben compartir el mismo estilo de bordes redondeados y tipografía. | M40: x
... B46: 36 | C46: Sincronización con el Controlador de Datos: Todas las tarjetas del dashboard deben consumir los datos procesados por el dashboard_controller.php. | M46: x
B47: 37
B48: 38
B49: 39
...

Sheet Instrumental FUN.
B2: SI | C2: Marque con una equis (X) si el sistema no cumple con la función descrita | T2: Volver
B3: NO | C3: Marque con una equis (X) si el sistema cumple con la función descrita
B4: ADI | C4: Marque con una equis (X) si el sistema debe adicionar la función descrita
B5: Observaciones: | D5: Espacio para complementar respuestas
B7: P
M8: Nivel de cumplimiento | P8: OBSERVACIONES
C9: REQUERIMIENTOS FUNCIONALES DE INSTRUMENTAL DENTRO DE LA PÁGINA WEB | M9: SI | N9: NO | O9: ADI
B12: 1 | C12: El sistema debe mostrar el botón "Volver al Inicio" que redirecciona al dashboard principal. | M12: x
B13: 2 | C13: El sistema debe mostrar la tarjeta "Instrumentos" y la tarjeta "Kits" junto con su breve descripción. | M13: x
B14: 3 | C14: Al dar click en la tarjeta "Instrumentos" el sistema debe abrir la gestión de instrumentos. | M14: x
B15: 4 | C15: Al entrar a una tarjeta, en la esquina superior izquierda debe estar el botón "Volver a Selección" que al interactuar con el, debe redirigir a la pestaña anterior con las tarjetas "Instrumentos" y "Kits". | M15: x
B16: 5 | C16: El sistema debe mostrar barras de búsqueda funcionales para facilitar la búsqueda en cada tarjeta. | M16: x
B17: 6 | C17: Las barras de búsqueda deben ser predictivas. | M17: x
B18: 7 | C18: El sistema debe limpiar los filtros de búsqueda automáticamente al navegar entre la gestión de Instrumentos y la gestión de Kits. | M18: x
B19: 8 | C19: Al extremo derecho de las barras de búsqueda debe estar el botón "Agregar Nuevo". | M19: x
B20: 9 | C20: Al dar click en la tarjeta "Agregar Nuevo" se debe abrir el modal "Nuevo registro" con los campos necesarios para agregar un nuevo instrumental o kit (Nombre Instrumento/kit, Cantidad, Lote,etc). | M20: x | R20: agregar campo para img
B21: 10 | C21: El modal de "Nuevo Registro" debe contar con los botones "Cancelar" que regresa al listado de instrumentos/kits y "Guardar" que registra los cambios realizados. | M21: x
B22: 11 | C22: En instrumentos, el sistema debe desplegar un listado con vistas en tarjeta de todos los instrumentos, con su cantidad disponible, vista previa de la imagen, nombre, especialización a la que pertenece, referencia (id), y botones para actualizar y eliminar. | M22: x | R22: quitar id
B23: 12 | C23: Al dar click en cualquier tarjeta de cualquier instrumento, el sistema debe abrir una vista detallada del instrumento (Mostrando su imagen, nombre, especializacion, referencia, cantidad actual, stock min/max, material, lote y su registro invima). | M23: x
B24: 13 | C24: Los modales de detalles de instrumentos deben tener su botón "x" o "Cerrar" en la parte inferior para cerrar los detalles de un instrumento. | M24: x
B25: 14 | C25: Al dar click en el botón "Editar" dentro del modal de detalles de un instrumento, el sistema debe abrir un nuevo modal llamado "Editar Instrumento" con los campos: Especialización, Nombre Instrumento, Cantidad Disponible, Lote, Registro INVIMA, Numeral en kit (Si aplica), Tipo de material, Imagen, Stock min/max), junto con los botones "Cancelar" y "Guardar". | M25: x
B26: 15 | C26: Desde la vista de tarjetas, al interactuar con el botón "Lápiz" también debe abrir el modal "Editar Instrumento". | M26: x
B27: 16 | C27: El modal "Editar Instrumento" debe traer información actual del instrumento, campos rellenados con los datos actuales del instrumento. | M27: x
B28: 17 | C28: Tras actualización exitosa, el sistema debe mostrar un modal con el título "¡Éxito!", una descripción y el botón "Aceptar" que cierra todos los modales al interactuar con él. | M28: x
B29: 18 | C29: El sistema no debe dejar guardar, ni crear un instrumento nuevo si hay campos en rojo, en dado caso que pase estas validaciones, debe mostrar un modal con el título "Datos inválidos" con un mensaje descriptivo y amigable para el usuario, junto con el botón "Cerrar", para volver a la edición o creación de un instrumento. | M29: x
B30: 19 | C30: El botón "Basura" en la vista tarjetas de instrumentos, al interactuar con el, debe mostrar un mensaje de confirmación al usuario antes de borrar un registro, al elegir la opción "Sí, eliminarlo", el sistema debe pasar el "ind_vivo" de ese instrumento a "FALSE". Si elige la opción "Cerrar", el modal de confirmación se debe cerrar dejando la vista de instrumentos. | M30: x
B31: 20 | C31: Al dar click en la tarjeta "Kits" el sistema debe abrir la gestión de kits. | M31: x
B32: 21 | C32: En Kits, el sistema debe desplegar un listado con vistas en tarjeta de todos los Kits, con su cantidad disponible, vista previa de la imagen, nombre, especialización a la que pertenece, referencia (id), y botones para actualizar y eliminar. | M32: x
B33: 22 | C33: Al dar click en cualquier tarjeta de cualquier kit, el sistema debe abrir una vista detallada del kit (Mostrando su imagen, nombre, especializacion, referencia, cantidad actual, stock min/max y el contenido del kit (instrumentos que tiene). | M33: x
B34: 23 | C34: Los modales de detalles de kits deben tener su botón "x" o "Cerrar" en la parte inferior para cerrar los detalles de un kit. | M34: x
... B52: 41 | C52: El catálogo de la Landing Page debe ser de "Solo lectura" (Modo vitrina), sin carrito de compras ni pasarela de pagos. | M52: x
B53: 42 | C53: Al hacer clic en un producto en la Landing Page, se debe mostrar su detalle, foto y un botón de "Contactar Asesor" (WhatsApp). | N53: x
B54: 43 | C54: El sistema administrativo debe permitir subir una foto referencial para cada "Producto Comercial". | M54: x | R54: Mejor que use la imagen ya asignada a instrumento o kits
B55: 44 | C55: Si el stock físico de un Instrumento o Kit llega a cero, el "Producto Comercial" asociado debe mostrarse automáticamente como "Agotado" en la Landing Page (o ocultarse, según preferencia). | N55: x
B56: 45 | C56: El Administrador debe poder editar el "Nombre Comercial" y "Descripción" del producto para la web, que puede ser diferente al nombre técnico del inventario. | M56: x
C59: REQUERIMIENTOS FUNCIONALES DE INSTRUMENTAL DENTRO DE LA BASE DE DATOS
B62: 1 | C62: El sistema debe permitir gestionar productos terminados clasificándolos como "Instrumentos" o "Kits". | M62: x
B63: 2 | C63: La función de gestión de productos debe impedir que un producto sea Instrumento y Kit simultáneamente. | M63: x
B64: 3 | C64: El sistema debe validar que el nombre del producto comercial no esté vacío. | M64: x
B65: 4 | C65: Al crear un producto, el sistema debe verificar que la referencia de inventario (ID Instrumento o ID Kit) exista y esté activa. | M65: x | R65: revisar
...

Sheet Instrumental NO FUN.
B2: SI | C2: Marque con una equis (X) si el sistema no cumple con la función descrita | T2: Volver
B3: NO | C3: Marque con una equis (X) si el sistema cumple con la función descrita
B4: ADI | C4: Marque con una equis (X) si el sistema debe adicionar la función descrita
B5: Observaciones: | D5: Espacio para complementar respuestas
B7: P
M8: Nivel de cumplimiento | P8: OBSERVACIONES
C9: REQUERIMIENTOS NO FUNCIONALES DE INSTRUMENTAL DENTRO DE LA PÁGINA WEB | M9: SI | N9: NO | O9: ADI
B12: 1 | C12: (UI / UX) La vista de selección debe utilizar tarjetas con el color institucional azul para "Instrumentos" y verde para "Kits". | M12: x
B13: 2 | C13: Las imágenes de las tarjetas de selección deben tener un tamaño de 100x100px y estar dentro de un contenedor circular blanco. | M13: x
B14: 3 | C14: El título de la tarjeta de selección debe utilizar mayúsculas sostenidas y un peso de fuente de 800 (Extra Bold). | M14: x
B15: 4 | C15: El hover de las tarjetas de selección debe aplicar un transform: scale(1.02) y una sombra azulada de rgba(54, 73, 143, 0.2). | M15: x
B16: 5 | C16: Las tarjetas de kits individuales deben mostrar un badge de disponibilidad en la esquina superior derecha con fondo blanco opaco (0.9). | M16: x
B17: 6 | C17: El encabezado de la gestión de instrumentos debe tener un padding de 20px y una animación de entrada 'fadeIn' de 0.3s. | M17: x
B18: 7 | C18: Los botones de acción en las tarjetas (Lápiz, Basura) deben tener una opacidad de 1 y ser siempre visibles. | M18: x
B19: 8 | C19: La tabla de datos debe tener encabezados pegajosos (sticky) con un z-index de 10 para facilitar el scroll. | M19: x
B20: 9 | C20: El color de la fila de encabezado en la tabla de instrumental debe coincidir con el color de la tarjeta de selección (#36498f). | M20: x
B21: 10 | C21: Los modales detallados deben cargar la imagen del instrumento con un tamaño máximo de 250px de altura. | M21: x
B22: 11 | C22: El scroll de la vista de kits debe ser vertical y suave, aplicado al contenedor principal .a2. | M22: x
B23: 12 | C23: Las insignias de "Bajo Stock" en las tarjetas de instrumental deben ser de color rojo #dc3545. | M23: x | R23: revisar
B24: 13 | C24: (USABILIDAD) La barra de búsqueda de instrumentos debe tener un ícono de lupa posicionado a 15px a la izquierda del input. | M24: x
B25: 14 | C25: El sistema debe filtrar los resultados automáticamente al ingresar texto, sin presionar "Enter". | M25: x
B26: 15 | C26: Los procesos de edición deben cargar datos previos en los campos del formulario automáticamente. | M26: x
B27: 16 | C27: El campo "Cantidad Disponible" en instrumental debe resaltarse visualmente si el valor es 0. | M27: x
C28: Los kits deben validar un contenido mínimo de 3 instrumentos y un máximo de 10 instrumentos vinculados. | M28: x
C29: El botón "Agregar Instrumento" en el modal de kits debe añadir dinámicamente campos de selección al formulario. | M29: x
B31: 18 | C31: Al entrar a la sección "Instrumental" los demás menus deben inhabilitarse de tal forma que no se pueda acceder a ellos por el menú lateral izquierdo. | M31: x
B32: 19 | C32: El botón del módulo activo ("Instrumental") debe incrementar su luminosidad y escala para diferenciarse de los módulos inactivos. | M32: x
B33: 20 | C33: Los elementos de navegación no permitidos deben presentar una opacidad reducida (0.5 o menor) como indicador de deshabilitación. | M33: x
B34: 21 | C34: Las opciones de menú deben mostrar un borde blanco definido y agrandar su tamaño relativo al detectar el cursor. | M34: x
B35: 22 | C35: Implementación de translateY negativo y aumento de box-shadow al pasar el mouse sobre las tarjetas de instrumentos o kits. | M35: x
B36: 23 | C36: Aparición de una barra azul en la parte inferior de la tarjeta "Instrumentos" al activarse el evento hover. | M36: x
B37: 24 | C37: Aparición de una barra verde en la parte inferior de la tarjeta "Kits" al activarse el evento hover. | M37: x
B38: 25 | C38: Todas las animaciones de escala y color deben tener una transición de 0.3s con curva ease. | M38: x
B39: 26 | C39: Uso prioritario de la fuente 'Segoe UI' o 'Montserrat' para garantizar la legibilidad de las descripciones técnicas. | M39: x
B40: 27 | C40: Uso unificado de border-radius (entre 10px y 25px) en todos los componentes interactivos para una estética moderna. | M40: x
B41: 28 | C41: Separación total de la hoja de estilos (estilos_menuPrincipal.css) de la estructura HTML y la lógica PHP. | M41: x
B42: 29 | C42: Uso de htmlspecialchars para prevenir ataques XSS al mostrar nombres de instrumentos. | N42: x | R42: ??
B43: 30 | C43: Integración de FontAwesome mediante CDN para asegurar que los glifos no retrasen el renderizado visual. | M43: x
B44: 31 | C44: Los mensajes de alerta o validación deben presentarse en modales con diseño coherente al resto del sistema. | M44: x
B45: 32 | C45: Animación de brillo o cambio de fondo en el botón "Volver al Inicio" para incitar a la acción. | M45: x
...

Sheet Materia prima FUN.
B2: SI | C2: Marque con una equis (X) si el sistema no cumple con la función descrita | V2: Volver
B3: NO | C3: Marque con una equis (X) si el sistema cumple con la función descrita
B4: ADI | C4: Marque con una equis (X) si el sistema debe adicionar la función descrita
B5: Observaciones: | D5: Espacio para complementar respuestas
B7: P
M8: Nivel de cumplimiento | P8: OBSERVACIONES
C9: REQUERIMIENTOS FUNCIONALES DE MATERIA PRIMA DENTRO DE LA PÁGINA WEB | M9: SI | N9: NO | O9: ADI
B12: 1 | C12: El sistema debe mostrar el botón "<- Volver al Inicio" que redirecciona al dashboard principal. | M12: x
B13: 2 | C13: Título "Materia Prima" visible. | M13: x
B14: 3 | C14: Botón "Registrar Movimiento" funcional, al dar click en este, el sistema debe abrir un modal con el título "Registrar Movimiento". | M14: x
B15: 4 | C15: Dentro del modal "Registrar Movimiento", el sistema debe mostrar los campos: Proveedor, Materia Prima, Tipo Movimiento, Cantidad Unidades, Observaciones. Con los botones "Cancelar" y "Registrar". | M15: x
B16: 5 | C16: El sistema debe obligar al usuario a seleccionar un proveedor para mostrar las materias primas correspondientes. Al seleccionar un proveedor, el sistema debe habilitar el campo "Materia Prima". Al hacer click sobre estos campos el sistema debe desplegar una listado. | M16: x
B17: 6 | C17: El campo "Tipo Movimiento" debe desplegar un listado al hacer click sobre este, con las siguientes opciones: "1. Entrada (Compra)", "2. Salida (Producción)", "3. Ajuste (Entrada +)" y "4. Daño (Salida -)". | M17: x
B18: 7 | C18: Botón "Cancelar" cierra el modal de "Registrar Movimiento". | M18: x
C19: Al llenar todos los campos de forma correcta y dar click en el botón "Registrar", el sistema debe mostrar un modal con el texto "¿Confirmar registro de movimiento? Esta acción afectará el inventario.", si el usuario da click en "Cancelar" este modal se cierra. | M19: x
C20: Si el usuario da click en "Aceptar", el botón "Registrar" debe pasar a "Guardando…", si todo salió bien, el sistema debe abrir un nuevo modal con el texto "Movimiento registrado con éxito.", tras dar click en el botón "Aceptar" el sistema debe cerrar todos los modales, y los cambios se deben haber realizado. | M20: x
B21: 8 | C21: Si el usuario da click en "Aceptar", el botón "Registrar" debe pasar a "Guardando…", si algo salio mal, el sistema debe abrir un nuevo modal con el texto "Error:" y un mensaje específico y amigable, tras dar click en el botón "Aceptar" el sistema debe dejar en la vista el panel "Registrar Movimiento" visible nuevamente. | M21: x
B22: 9 | C22: El sistema debe mostrar una vista en tarjetas de las categorías disponibles junto a su nombre. | M22: x
B23: 10 | C23: Al dar click en una tarjeta, el sistema debe abrir un nuevo menú para gestionar las materias primas de la categoría seleccionada. | M23: x
B24: 11 | C24: El sistema debe mostrar el botón "<- Volver a categorías" que redirige a la vista anterior de categorías. | M24: x
B25: 12 | C25: El sistema debe mostrar el título "Materias Primas: (Categoría Seleccionada)". | M25: x
B26: 13 | C26: El sistema debe mostrar el botón " + Agregar Nueva Materia" que al dar click en este, el sistema debe abrir un nuevo modal-formulario con los siguientes campos: Nombre Materia Prima, Stock Mínimo / Máximo, Imagen, Proveedor, Valor de Medida, Unidad de medida Lote Inicial, Tipo Material, Cantidad Inicial. | M26: x
B27: 14 | C27: Los campos "Proveedor" y "Unidad de Medida" deben desplegar listas de opciones al dar click en estas. | M27: x
B28: 15 | C28: Al dar click en el botón "Guardar" y todos los campos sean válidos, el sistema debe abrir un modal con el título "¡Éxito!" con el mensaje "Registro guardado correctamente" y el botón "Aceptar", que al dar click en este, cierra todos los modales y dejar visible la gestión de la categoría seleccioanda anteriormente. | M28: x
B29: 16 | C29: Al dar click en el botón "Guardar" y algún campo sea inválido, el sistema debe abrir un modal con el título "Datos inválidos" con el mensaje "Por favor corrija los campos marcados en rojo." y el botón "Cerrar", que al dar click en este, cierra el modal de error y deja visible el modal de creación de la materia prima. | M29: x
